[2021-11-14 15:23:02,755] {taskinstance.py:896} INFO - Dependencies all met for <TaskInstance: PostgresOperator_dag.create_table 2021-11-14T15:23:00.031300+00:00 [queued]>
[2021-11-14 15:23:03,398] {taskinstance.py:896} INFO - Dependencies all met for <TaskInstance: PostgresOperator_dag.create_table 2021-11-14T15:23:00.031300+00:00 [queued]>
[2021-11-14 15:23:03,399] {taskinstance.py:1087} INFO - 
--------------------------------------------------------------------------------
[2021-11-14 15:23:03,399] {taskinstance.py:1088} INFO - Starting attempt 1 of 1
[2021-11-14 15:23:03,400] {taskinstance.py:1089} INFO - 
--------------------------------------------------------------------------------
[2021-11-14 15:23:03,568] {taskinstance.py:1107} INFO - Executing <Task(PostgresOperator): create_table> on 2021-11-14T15:23:00.031300+00:00
[2021-11-14 15:23:03,572] {standard_task_runner.py:52} INFO - Started process 4533 to run task
[2021-11-14 15:23:03,576] {standard_task_runner.py:76} INFO - Running: ['***', 'tasks', 'run', 'PostgresOperator_dag', 'create_table', '2021-11-14T15:23:00.031300+00:00', '--job-id', '14', '--pool', 'default_pool', '--raw', '--subdir', 'DAGS_FOLDER/test_dag.py', '--cfg-path', '/tmp/tmpnlvkct5s', '--error-file', '/tmp/tmp_jmk6m68']
[2021-11-14 15:23:03,577] {standard_task_runner.py:77} INFO - Job 14: Subtask create_table
[2021-11-14 15:23:03,732] {logging_mixin.py:104} INFO - Running <TaskInstance: PostgresOperator_dag.create_table 2021-11-14T15:23:00.031300+00:00 [running]> on host ce5fde95fe25
[2021-11-14 15:23:03,838] {taskinstance.py:1302} INFO - Exporting the following env vars:
AIRFLOW_CTX_DAG_OWNER=***
AIRFLOW_CTX_DAG_ID=PostgresOperator_dag
AIRFLOW_CTX_TASK_ID=create_table
AIRFLOW_CTX_EXECUTION_DATE=2021-11-14T15:23:00.031300+00:00
AIRFLOW_CTX_DAG_RUN_ID=manual__2021-11-14T15:23:00.031300+00:00
[2021-11-14 15:23:03,840] {postgres.py:68} INFO - Executing: CREATE TABLE new_table(
            custom_id integer NOT NULL, timestamp TIMESTAMP NOT NULL, user_id VARCHAR (50) NOT NULL
            );
[2021-11-14 15:23:03,857] {base.py:78} INFO - Using connection to: id: ***_db_x. Host: x, Port: 5432, Schema: , Login: postgres, Password: ***, extra: {}
[2021-11-14 15:23:03,861] {taskinstance.py:1501} ERROR - Task failed with exception
Traceback (most recent call last):
  File "/home/airflow/.local/lib/python3.6/site-packages/airflow/models/taskinstance.py", line 1157, in _run_raw_task
    self._prepare_and_execute_task_with_callbacks(context, task)
  File "/home/airflow/.local/lib/python3.6/site-packages/airflow/models/taskinstance.py", line 1331, in _prepare_and_execute_task_with_callbacks
    result = self._execute_task(context, task_copy)
  File "/home/airflow/.local/lib/python3.6/site-packages/airflow/models/taskinstance.py", line 1361, in _execute_task
    result = task_copy.execute(context=context)
  File "/home/airflow/.local/lib/python3.6/site-packages/airflow/providers/postgres/operators/postgres.py", line 70, in execute
    self.hook.run(self.sql, self.autocommit, parameters=self.parameters)
  File "/home/airflow/.local/lib/python3.6/site-packages/airflow/hooks/dbapi.py", line 177, in run
    with closing(self.get_conn()) as conn:
  File "/home/airflow/.local/lib/python3.6/site-packages/airflow/providers/postgres/hooks/postgres.py", line 115, in get_conn
    self.conn = psycopg2.connect(**conn_args)
  File "/home/airflow/.local/lib/python3.6/site-packages/psycopg2/__init__.py", line 122, in connect
    conn = _connect(dsn, connection_factory=connection_factory, **kwasync)
psycopg2.OperationalError: could not translate host name "x" to address: Temporary failure in name resolution

[2021-11-14 15:23:03,866] {taskinstance.py:1551} INFO - Marking task as FAILED. dag_id=PostgresOperator_dag, task_id=create_table, execution_date=20211114T152300, start_date=20211114T152302, end_date=20211114T152303
[2021-11-14 15:23:03,919] {local_task_job.py:149} INFO - Task exited with return code 1
