[2021-11-14 15:12:08,872] {taskinstance.py:896} INFO - Dependencies all met for <TaskInstance: PostgresOperator_dag.create_table 2021-11-14T15:12:06.655718+00:00 [queued]>
[2021-11-14 15:12:08,907] {taskinstance.py:896} INFO - Dependencies all met for <TaskInstance: PostgresOperator_dag.create_table 2021-11-14T15:12:06.655718+00:00 [queued]>
[2021-11-14 15:12:08,908] {taskinstance.py:1087} INFO - 
--------------------------------------------------------------------------------
[2021-11-14 15:12:08,908] {taskinstance.py:1088} INFO - Starting attempt 1 of 1
[2021-11-14 15:12:08,908] {taskinstance.py:1089} INFO - 
--------------------------------------------------------------------------------
[2021-11-14 15:12:08,928] {taskinstance.py:1107} INFO - Executing <Task(PostgresOperator): create_table> on 2021-11-14T15:12:06.655718+00:00
[2021-11-14 15:12:08,940] {standard_task_runner.py:52} INFO - Started process 3867 to run task
[2021-11-14 15:12:08,956] {standard_task_runner.py:76} INFO - Running: ['***', 'tasks', 'run', 'PostgresOperator_dag', 'create_table', '2021-11-14T15:12:06.655718+00:00', '--job-id', '8', '--pool', 'default_pool', '--raw', '--subdir', 'DAGS_FOLDER/test_dag.py', '--cfg-path', '/tmp/tmp7bzr8ccq', '--error-file', '/tmp/tmpe6jeebuj']
[2021-11-14 15:12:08,960] {standard_task_runner.py:77} INFO - Job 8: Subtask create_table
[2021-11-14 15:12:09,086] {logging_mixin.py:104} INFO - Running <TaskInstance: PostgresOperator_dag.create_table 2021-11-14T15:12:06.655718+00:00 [running]> on host ce5fde95fe25
[2021-11-14 15:12:09,311] {taskinstance.py:1302} INFO - Exporting the following env vars:
AIRFLOW_CTX_DAG_OWNER=***
AIRFLOW_CTX_DAG_ID=PostgresOperator_dag
AIRFLOW_CTX_TASK_ID=create_table
AIRFLOW_CTX_EXECUTION_DATE=2021-11-14T15:12:06.655718+00:00
AIRFLOW_CTX_DAG_RUN_ID=manual__2021-11-14T15:12:06.655718+00:00
[2021-11-14 15:12:09,312] {postgres.py:68} INFO - Executing: CREATE TABLE new_table(
            custom_id integer NOT NULL, timestamp TIMESTAMP NOT NULL, user_id VARCHAR (50) NOT NULL
            );
[2021-11-14 15:12:09,332] {base.py:78} INFO - Using connection to: id: ***_db_x. Host: postgres, Port: 5432, Schema: , Login: ali, Password: ***, extra: {}
[2021-11-14 15:12:09,341] {taskinstance.py:1501} ERROR - Task failed with exception
Traceback (most recent call last):
  File "/home/airflow/.local/lib/python3.6/site-packages/airflow/models/taskinstance.py", line 1157, in _run_raw_task
    self._prepare_and_execute_task_with_callbacks(context, task)
  File "/home/airflow/.local/lib/python3.6/site-packages/airflow/models/taskinstance.py", line 1331, in _prepare_and_execute_task_with_callbacks
    result = self._execute_task(context, task_copy)
  File "/home/airflow/.local/lib/python3.6/site-packages/airflow/models/taskinstance.py", line 1361, in _execute_task
    result = task_copy.execute(context=context)
  File "/home/airflow/.local/lib/python3.6/site-packages/airflow/providers/postgres/operators/postgres.py", line 70, in execute
    self.hook.run(self.sql, self.autocommit, parameters=self.parameters)
  File "/home/airflow/.local/lib/python3.6/site-packages/airflow/hooks/dbapi.py", line 177, in run
    with closing(self.get_conn()) as conn:
  File "/home/airflow/.local/lib/python3.6/site-packages/airflow/providers/postgres/hooks/postgres.py", line 115, in get_conn
    self.conn = psycopg2.connect(**conn_args)
  File "/home/airflow/.local/lib/python3.6/site-packages/psycopg2/__init__.py", line 122, in connect
    conn = _connect(dsn, connection_factory=connection_factory, **kwasync)
psycopg2.OperationalError: FATAL:  *** authentication failed for user "ali"

[2021-11-14 15:12:09,345] {taskinstance.py:1551} INFO - Marking task as FAILED. dag_id=PostgresOperator_dag, task_id=create_table, execution_date=20211114T151206, start_date=20211114T151208, end_date=20211114T151209
[2021-11-14 15:12:09,622] {local_task_job.py:149} INFO - Task exited with return code 1
